[2024-02-27T16:59:23.481+0000] {taskinstance.py:1979} INFO - Dependencies all met for dep_context=non-requeueable deps ti=<TaskInstance: dataIngestionDag.task_extract_earthquake_data manual__2024-02-27T16:59:03.058299+00:00 [queued]>
[2024-02-27T16:59:23.487+0000] {taskinstance.py:1979} INFO - Dependencies all met for dep_context=requeueable deps ti=<TaskInstance: dataIngestionDag.task_extract_earthquake_data manual__2024-02-27T16:59:03.058299+00:00 [queued]>
[2024-02-27T16:59:23.487+0000] {taskinstance.py:2193} INFO - Starting attempt 2 of 3
[2024-02-27T16:59:23.502+0000] {taskinstance.py:2214} INFO - Executing <Task(PythonOperator): task_extract_earthquake_data> on 2024-02-27 16:59:03.058299+00:00
[2024-02-27T16:59:23.506+0000] {standard_task_runner.py:60} INFO - Started process 9156 to run task
[2024-02-27T16:59:23.509+0000] {standard_task_runner.py:87} INFO - Running: ['airflow', 'tasks', 'run', 'dataIngestionDag', 'task_extract_earthquake_data', 'manual__2024-02-27T16:59:03.058299+00:00', '--job-id', '36', '--raw', '--subdir', 'DAGS_FOLDER/ingestionPipeline.py', '--cfg-path', '/tmp/tmpr4c2l6v6']
[2024-02-27T16:59:23.511+0000] {standard_task_runner.py:88} INFO - Job 36: Subtask task_extract_earthquake_data
[2024-02-27T16:59:23.548+0000] {task_command.py:423} INFO - Running <TaskInstance: dataIngestionDag.task_extract_earthquake_data manual__2024-02-27T16:59:03.058299+00:00 [running]> on host ip-172-31-12-93.ap-south-1.compute.internal
[2024-02-27T16:59:23.601+0000] {taskinstance.py:2510} INFO - Exporting env vars: AIRFLOW_CTX_DAG_EMAIL='shubh.sehgal2506@gmail.com' AIRFLOW_CTX_DAG_OWNER='shubh-airflow' AIRFLOW_CTX_DAG_ID='dataIngestionDag' AIRFLOW_CTX_TASK_ID='task_extract_earthquake_data' AIRFLOW_CTX_EXECUTION_DATE='2024-02-27T16:59:03.058299+00:00' AIRFLOW_CTX_TRY_NUMBER='2' AIRFLOW_CTX_DAG_RUN_ID='manual__2024-02-27T16:59:03.058299+00:00'
[2024-02-27T16:59:23.602+0000] {taskinstance.py:2728} ERROR - Task failed with exception
Traceback (most recent call last):
  File "/usr/local/lib/python3.10/dist-packages/airflow/models/taskinstance.py", line 444, in _execute_task
    result = _execute_callable(context=context, **execute_callable_kwargs)
  File "/usr/local/lib/python3.10/dist-packages/airflow/models/taskinstance.py", line 414, in _execute_callable
    return execute_callable(context=context, **execute_callable_kwargs)
  File "/usr/local/lib/python3.10/dist-packages/airflow/operators/python.py", line 200, in execute
    return_value = self.execute_callable()
  File "/usr/local/lib/python3.10/dist-packages/airflow/operators/python.py", line 217, in execute_callable
    return self.python_callable(*self.op_args, **self.op_kwargs)
TypeError: extractData() missing 5 required positional arguments: 'HISTORICAL_DATA_YEAR', 'HISTORICAL_DATA_MONTH', 'HISTORICAL_DATA_DAY', 'NUMBER_OF_DAYS', and 'API_KEY'
[2024-02-27T16:59:23.605+0000] {taskinstance.py:1149} INFO - Marking task as UP_FOR_RETRY. dag_id=dataIngestionDag, task_id=task_extract_earthquake_data, execution_date=20240227T165903, start_date=20240227T165923, end_date=20240227T165923
[2024-02-27T16:59:23.616+0000] {base.py:83} INFO - Using connection ID 'smtp_default' for task execution.
[2024-02-27T16:59:23.616+0000] {email.py:270} INFO - Email alerting: attempt 1
[2024-02-27T16:59:25.729+0000] {base.py:83} INFO - Using connection ID 'smtp_default' for task execution.
[2024-02-27T16:59:25.729+0000] {email.py:270} INFO - Email alerting: attempt 1
[2024-02-27T16:59:27.799+0000] {taskinstance.py:837} ERROR - Failed to send email to: ['shubh.sehgal2506@gmail.com']
Traceback (most recent call last):
  File "/usr/local/lib/python3.10/dist-packages/airflow/models/taskinstance.py", line 2357, in _run_raw_task
    self._execute_task_with_callbacks(context, test_mode, session=session)
  File "/usr/local/lib/python3.10/dist-packages/airflow/models/taskinstance.py", line 2529, in _execute_task_with_callbacks
    result = self._execute_task(context, task_orig)
  File "/usr/local/lib/python3.10/dist-packages/airflow/models/taskinstance.py", line 2546, in _execute_task
    return _execute_task(self, context, task_orig)
  File "/usr/local/lib/python3.10/dist-packages/airflow/models/taskinstance.py", line 444, in _execute_task
    result = _execute_callable(context=context, **execute_callable_kwargs)
  File "/usr/local/lib/python3.10/dist-packages/airflow/models/taskinstance.py", line 414, in _execute_callable
    return execute_callable(context=context, **execute_callable_kwargs)
  File "/usr/local/lib/python3.10/dist-packages/airflow/operators/python.py", line 200, in execute
    return_value = self.execute_callable()
  File "/usr/local/lib/python3.10/dist-packages/airflow/operators/python.py", line 217, in execute_callable
    return self.python_callable(*self.op_args, **self.op_kwargs)
TypeError: extractData() missing 5 required positional arguments: 'HISTORICAL_DATA_YEAR', 'HISTORICAL_DATA_MONTH', 'HISTORICAL_DATA_DAY', 'NUMBER_OF_DAYS', and 'API_KEY'

During handling of the above exception, another exception occurred:

Traceback (most recent call last):
  File "/usr/local/lib/python3.10/dist-packages/airflow/models/taskinstance.py", line 1011, in _email_alert
    send_email(task.email, subject, html_content)
  File "/usr/local/lib/python3.10/dist-packages/airflow/utils/email.py", line 80, in send_email
    return backend(
  File "/usr/local/lib/python3.10/dist-packages/airflow/utils/email.py", line 154, in send_email_smtp
    send_mime_email(e_from=mail_from, e_to=recipients, mime_msg=msg, conn_id=conn_id, dryrun=dryrun)
  File "/usr/local/lib/python3.10/dist-packages/airflow/utils/email.py", line 280, in send_mime_email
    smtp_conn.login(smtp_user, smtp_password)
  File "/usr/lib/python3.10/smtplib.py", line 750, in login
    raise last_exception
  File "/usr/lib/python3.10/smtplib.py", line 739, in login
    (code, resp) = self.auth(
  File "/usr/lib/python3.10/smtplib.py", line 662, in auth
    raise SMTPAuthenticationError(code, resp)
smtplib.SMTPAuthenticationError: (535, b'5.7.8 Username and Password not accepted. For more information, go to\n5.7.8  https://support.google.com/mail/?p=BadCredentials d4-20020a17090b004400b0029ab5abcbe1sm5164998pjt.20 - gsmtp')

During handling of the above exception, another exception occurred:

Traceback (most recent call last):
  File "/usr/local/lib/python3.10/dist-packages/airflow/models/taskinstance.py", line 835, in _handle_failure
    task_instance.email_alert(error, failure_context["task"])
  File "/usr/local/lib/python3.10/dist-packages/airflow/models/taskinstance.py", line 2976, in email_alert
    _email_alert(task_instance=self, exception=exception, task=task)
  File "/usr/local/lib/python3.10/dist-packages/airflow/models/taskinstance.py", line 1013, in _email_alert
    send_email(task.email, subject, html_content_err)
  File "/usr/local/lib/python3.10/dist-packages/airflow/utils/email.py", line 80, in send_email
    return backend(
  File "/usr/local/lib/python3.10/dist-packages/airflow/utils/email.py", line 154, in send_email_smtp
    send_mime_email(e_from=mail_from, e_to=recipients, mime_msg=msg, conn_id=conn_id, dryrun=dryrun)
  File "/usr/local/lib/python3.10/dist-packages/airflow/utils/email.py", line 280, in send_mime_email
    smtp_conn.login(smtp_user, smtp_password)
  File "/usr/lib/python3.10/smtplib.py", line 750, in login
    raise last_exception
  File "/usr/lib/python3.10/smtplib.py", line 739, in login
    (code, resp) = self.auth(
  File "/usr/lib/python3.10/smtplib.py", line 662, in auth
    raise SMTPAuthenticationError(code, resp)
smtplib.SMTPAuthenticationError: (535, b'5.7.8 Username and Password not accepted. For more information, go to\n5.7.8  https://support.google.com/mail/?p=BadCredentials 13-20020a170902ee4d00b001dc6b99af70sm1752177plo.108 - gsmtp')
[2024-02-27T16:59:27.809+0000] {standard_task_runner.py:107} ERROR - Failed to execute job 36 for task task_extract_earthquake_data (extractData() missing 5 required positional arguments: 'HISTORICAL_DATA_YEAR', 'HISTORICAL_DATA_MONTH', 'HISTORICAL_DATA_DAY', 'NUMBER_OF_DAYS', and 'API_KEY'; 9156)
[2024-02-27T16:59:27.817+0000] {local_task_job_runner.py:234} INFO - Task exited with return code 1
[2024-02-27T16:59:27.830+0000] {taskinstance.py:3309} INFO - 0 downstream tasks scheduled from follow-on schedule check
