[2024-03-02T05:36:14.933+0000] {taskinstance.py:1979} INFO - Dependencies all met for dep_context=non-requeueable deps ti=<TaskInstance: dataIngestionDag.get_clean_csv_from_s3 scheduled__2024-03-01T00:00:00+00:00 [queued]>
[2024-03-02T05:36:14.940+0000] {taskinstance.py:1979} INFO - Dependencies all met for dep_context=requeueable deps ti=<TaskInstance: dataIngestionDag.get_clean_csv_from_s3 scheduled__2024-03-01T00:00:00+00:00 [queued]>
[2024-03-02T05:36:14.940+0000] {taskinstance.py:2193} INFO - Starting attempt 1 of 3
[2024-03-02T05:36:14.956+0000] {taskinstance.py:2214} INFO - Executing <Task(PythonOperator): get_clean_csv_from_s3> on 2024-03-01 00:00:00+00:00
[2024-03-02T05:36:14.961+0000] {standard_task_runner.py:60} INFO - Started process 2417 to run task
[2024-03-02T05:36:14.965+0000] {standard_task_runner.py:87} INFO - Running: ['airflow', 'tasks', 'run', 'dataIngestionDag', 'get_clean_csv_from_s3', 'scheduled__2024-03-01T00:00:00+00:00', '--job-id', '171', '--raw', '--subdir', 'DAGS_FOLDER/ingestionPipeline.py', '--cfg-path', '/tmp/tmpt8x0z6ln']
[2024-03-02T05:36:14.967+0000] {standard_task_runner.py:88} INFO - Job 171: Subtask get_clean_csv_from_s3
[2024-03-02T05:36:15.011+0000] {task_command.py:423} INFO - Running <TaskInstance: dataIngestionDag.get_clean_csv_from_s3 scheduled__2024-03-01T00:00:00+00:00 [running]> on host ip-172-31-12-93.ap-south-1.compute.internal
[2024-03-02T05:36:15.083+0000] {taskinstance.py:2510} INFO - Exporting env vars: AIRFLOW_CTX_DAG_EMAIL='shubh.sehgal2506@gmail.com' AIRFLOW_CTX_DAG_OWNER='shubh-airflow' AIRFLOW_CTX_DAG_ID='dataIngestionDag' AIRFLOW_CTX_TASK_ID='get_clean_csv_from_s3' AIRFLOW_CTX_EXECUTION_DATE='2024-03-01T00:00:00+00:00' AIRFLOW_CTX_TRY_NUMBER='1' AIRFLOW_CTX_DAG_RUN_ID='scheduled__2024-03-01T00:00:00+00:00'
[2024-03-02T05:36:15.306+0000] {taskinstance.py:2728} ERROR - Task failed with exception
Traceback (most recent call last):
  File "/usr/local/lib/python3.10/dist-packages/airflow/models/taskinstance.py", line 444, in _execute_task
    result = _execute_callable(context=context, **execute_callable_kwargs)
  File "/usr/local/lib/python3.10/dist-packages/airflow/models/taskinstance.py", line 414, in _execute_callable
    return execute_callable(context=context, **execute_callable_kwargs)
  File "/usr/local/lib/python3.10/dist-packages/airflow/operators/python.py", line 200, in execute
    return_value = self.execute_callable()
  File "/usr/local/lib/python3.10/dist-packages/airflow/operators/python.py", line 217, in execute_callable
    return self.python_callable(*self.op_args, **self.op_kwargs)
  File "/home/ubuntu/airflow/pythonScript.py", line 69, in getCleanedDataFromS3
    s3.Bucket(CLEANED_S3_BUCKET_NAME).download_file(Key=CLEANED_CSV_FILE_NAME, Filename=CLEANED_CSV_FILE_NAME)
  File "/usr/local/lib/python3.10/dist-packages/boto3/s3/inject.py", line 279, in bucket_download_file
    return self.meta.client.download_file(
  File "/usr/local/lib/python3.10/dist-packages/boto3/s3/inject.py", line 192, in download_file
    return transfer.download_file(
  File "/usr/local/lib/python3.10/dist-packages/boto3/s3/transfer.py", line 405, in download_file
    future.result()
  File "/usr/local/lib/python3.10/dist-packages/s3transfer/futures.py", line 103, in result
    return self._coordinator.result()
  File "/usr/local/lib/python3.10/dist-packages/s3transfer/futures.py", line 266, in result
    raise self._exception
  File "/usr/local/lib/python3.10/dist-packages/s3transfer/tasks.py", line 269, in _main
    self._submit(transfer_future=transfer_future, **kwargs)
  File "/usr/local/lib/python3.10/dist-packages/s3transfer/download.py", line 354, in _submit
    response = client.head_object(
  File "/usr/local/lib/python3.10/dist-packages/botocore/client.py", line 553, in _api_call
    return self._make_api_call(operation_name, kwargs)
  File "/usr/local/lib/python3.10/dist-packages/botocore/client.py", line 1009, in _make_api_call
    raise error_class(parsed_response, operation_name)
botocore.exceptions.ClientError: An error occurred (404) when calling the HeadObject operation: Not Found
[2024-03-02T05:36:15.319+0000] {taskinstance.py:1149} INFO - Marking task as UP_FOR_RETRY. dag_id=dataIngestionDag, task_id=get_clean_csv_from_s3, execution_date=20240301T000000, start_date=20240302T053614, end_date=20240302T053615
[2024-03-02T05:36:15.333+0000] {standard_task_runner.py:107} ERROR - Failed to execute job 171 for task get_clean_csv_from_s3 (An error occurred (404) when calling the HeadObject operation: Not Found; 2417)
[2024-03-02T05:36:15.345+0000] {local_task_job_runner.py:234} INFO - Task exited with return code 1
[2024-03-02T05:36:15.360+0000] {taskinstance.py:3309} INFO - 0 downstream tasks scheduled from follow-on schedule check
