[2024-02-27T17:23:09.205+0000] {taskinstance.py:1979} INFO - Dependencies all met for dep_context=non-requeueable deps ti=<TaskInstance: dataIngestionDag.task_extract_earthquake_data manual__2024-02-27T17:17:10.322096+00:00 [queued]>
[2024-02-27T17:23:09.212+0000] {taskinstance.py:1979} INFO - Dependencies all met for dep_context=requeueable deps ti=<TaskInstance: dataIngestionDag.task_extract_earthquake_data manual__2024-02-27T17:17:10.322096+00:00 [queued]>
[2024-02-27T17:23:09.212+0000] {taskinstance.py:2193} INFO - Starting attempt 4 of 6
[2024-02-27T17:23:09.230+0000] {taskinstance.py:2214} INFO - Executing <Task(PythonOperator): task_extract_earthquake_data> on 2024-02-27 17:17:10.322096+00:00
[2024-02-27T17:23:09.234+0000] {standard_task_runner.py:60} INFO - Started process 16222 to run task
[2024-02-27T17:23:09.237+0000] {standard_task_runner.py:87} INFO - Running: ['airflow', 'tasks', 'run', 'dataIngestionDag', 'task_extract_earthquake_data', 'manual__2024-02-27T17:17:10.322096+00:00', '--job-id', '61', '--raw', '--subdir', 'DAGS_FOLDER/ingestionPipeline.py', '--cfg-path', '/tmp/tmp1dba_4mc']
[2024-02-27T17:23:09.239+0000] {standard_task_runner.py:88} INFO - Job 61: Subtask task_extract_earthquake_data
[2024-02-27T17:23:09.276+0000] {task_command.py:423} INFO - Running <TaskInstance: dataIngestionDag.task_extract_earthquake_data manual__2024-02-27T17:17:10.322096+00:00 [running]> on host ip-172-31-12-93.ap-south-1.compute.internal
[2024-02-27T17:23:09.329+0000] {taskinstance.py:2510} INFO - Exporting env vars: AIRFLOW_CTX_DAG_EMAIL='shubh.sehgal2506@gmail.com' AIRFLOW_CTX_DAG_OWNER='shubh-airflow' AIRFLOW_CTX_DAG_ID='dataIngestionDag' AIRFLOW_CTX_TASK_ID='task_extract_earthquake_data' AIRFLOW_CTX_EXECUTION_DATE='2024-02-27T17:17:10.322096+00:00' AIRFLOW_CTX_TRY_NUMBER='4' AIRFLOW_CTX_DAG_RUN_ID='manual__2024-02-27T17:17:10.322096+00:00'
[2024-02-27T17:23:09.330+0000] {taskinstance.py:2728} ERROR - Task failed with exception
Traceback (most recent call last):
  File "/usr/local/lib/python3.10/dist-packages/airflow/models/taskinstance.py", line 444, in _execute_task
    result = _execute_callable(context=context, **execute_callable_kwargs)
  File "/usr/local/lib/python3.10/dist-packages/airflow/models/taskinstance.py", line 414, in _execute_callable
    return execute_callable(context=context, **execute_callable_kwargs)
  File "/usr/local/lib/python3.10/dist-packages/airflow/operators/python.py", line 200, in execute
    return_value = self.execute_callable()
  File "/usr/local/lib/python3.10/dist-packages/airflow/operators/python.py", line 217, in execute_callable
    return self.python_callable(*self.op_args, **self.op_kwargs)
  File "/home/ubuntu/airflow/pythonScript.py", line 33, in extractData
    earthquakes_df = pd.concat([filter_earthquakes(get_earthquakes(date(2022, 1, 1) - timedelta(i))) for i in range(100)])
  File "/home/ubuntu/airflow/pythonScript.py", line 33, in <listcomp>
    earthquakes_df = pd.concat([filter_earthquakes(get_earthquakes(date(2022, 1, 1) - timedelta(i))) for i in range(100)])
TypeError: 'datetime.date' object is not callable
[2024-02-27T17:23:09.334+0000] {taskinstance.py:1149} INFO - Marking task as UP_FOR_RETRY. dag_id=dataIngestionDag, task_id=task_extract_earthquake_data, execution_date=20240227T171710, start_date=20240227T172309, end_date=20240227T172309
[2024-02-27T17:23:09.345+0000] {standard_task_runner.py:107} ERROR - Failed to execute job 61 for task task_extract_earthquake_data ('datetime.date' object is not callable; 16222)
[2024-02-27T17:23:09.369+0000] {local_task_job_runner.py:234} INFO - Task exited with return code 1
[2024-02-27T17:23:09.382+0000] {taskinstance.py:3309} INFO - 0 downstream tasks scheduled from follow-on schedule check
