[2024-02-27T17:14:06.495+0000] {taskinstance.py:1979} INFO - Dependencies all met for dep_context=non-requeueable deps ti=<TaskInstance: dataIngestionDag.task_extract_earthquake_data manual__2024-02-27T17:13:45.181922+00:00 [queued]>
[2024-02-27T17:14:06.501+0000] {taskinstance.py:1979} INFO - Dependencies all met for dep_context=requeueable deps ti=<TaskInstance: dataIngestionDag.task_extract_earthquake_data manual__2024-02-27T17:13:45.181922+00:00 [queued]>
[2024-02-27T17:14:06.502+0000] {taskinstance.py:2193} INFO - Starting attempt 2 of 3
[2024-02-27T17:14:06.517+0000] {taskinstance.py:2214} INFO - Executing <Task(PythonOperator): task_extract_earthquake_data> on 2024-02-27 17:13:45.181922+00:00
[2024-02-27T17:14:06.522+0000] {standard_task_runner.py:60} INFO - Started process 12849 to run task
[2024-02-27T17:14:06.525+0000] {standard_task_runner.py:87} INFO - Running: ['airflow', 'tasks', 'run', 'dataIngestionDag', 'task_extract_earthquake_data', 'manual__2024-02-27T17:13:45.181922+00:00', '--job-id', '43', '--raw', '--subdir', 'DAGS_FOLDER/ingestionPipeline.py', '--cfg-path', '/tmp/tmp72hu4o9i']
[2024-02-27T17:14:06.527+0000] {standard_task_runner.py:88} INFO - Job 43: Subtask task_extract_earthquake_data
[2024-02-27T17:14:06.567+0000] {task_command.py:423} INFO - Running <TaskInstance: dataIngestionDag.task_extract_earthquake_data manual__2024-02-27T17:13:45.181922+00:00 [running]> on host ip-172-31-12-93.ap-south-1.compute.internal
[2024-02-27T17:14:06.622+0000] {taskinstance.py:2510} INFO - Exporting env vars: AIRFLOW_CTX_DAG_EMAIL='shubh.sehgal2506@gmail.com' AIRFLOW_CTX_DAG_OWNER='shubh-airflow' AIRFLOW_CTX_DAG_ID='dataIngestionDag' AIRFLOW_CTX_TASK_ID='task_extract_earthquake_data' AIRFLOW_CTX_EXECUTION_DATE='2024-02-27T17:13:45.181922+00:00' AIRFLOW_CTX_TRY_NUMBER='2' AIRFLOW_CTX_DAG_RUN_ID='manual__2024-02-27T17:13:45.181922+00:00'
[2024-02-27T17:14:06.623+0000] {taskinstance.py:2728} ERROR - Task failed with exception
Traceback (most recent call last):
  File "/usr/local/lib/python3.10/dist-packages/airflow/models/taskinstance.py", line 444, in _execute_task
    result = _execute_callable(context=context, **execute_callable_kwargs)
  File "/usr/local/lib/python3.10/dist-packages/airflow/models/taskinstance.py", line 414, in _execute_callable
    return execute_callable(context=context, **execute_callable_kwargs)
  File "/usr/local/lib/python3.10/dist-packages/airflow/operators/python.py", line 200, in execute
    return_value = self.execute_callable()
  File "/usr/local/lib/python3.10/dist-packages/airflow/operators/python.py", line 217, in execute_callable
    return self.python_callable(*self.op_args, **self.op_kwargs)
  File "/home/ubuntu/airflow/pythonScript.py", line 33, in extractData
    earthquakes_df = pd.concat([filter_earthquakes(get_earthquakes(date(2022, 1, 1) - timedelta(i))) for i in range(100)])
  File "/home/ubuntu/airflow/pythonScript.py", line 33, in <listcomp>
    earthquakes_df = pd.concat([filter_earthquakes(get_earthquakes(date(2022, 1, 1) - timedelta(i))) for i in range(100)])
TypeError: 'datetime.date' object is not callable
[2024-02-27T17:14:06.626+0000] {taskinstance.py:1149} INFO - Marking task as UP_FOR_RETRY. dag_id=dataIngestionDag, task_id=task_extract_earthquake_data, execution_date=20240227T171345, start_date=20240227T171406, end_date=20240227T171406
[2024-02-27T17:14:06.646+0000] {base.py:83} INFO - Using connection ID 'smtp_default' for task execution.
[2024-02-27T17:14:06.647+0000] {email.py:270} INFO - Email alerting: attempt 1
[2024-02-27T17:14:08.789+0000] {base.py:83} INFO - Using connection ID 'smtp_default' for task execution.
[2024-02-27T17:14:08.789+0000] {email.py:270} INFO - Email alerting: attempt 1
[2024-02-27T17:14:10.987+0000] {taskinstance.py:837} ERROR - Failed to send email to: ['shubh.sehgal2506@gmail.com']
Traceback (most recent call last):
  File "/usr/local/lib/python3.10/dist-packages/airflow/models/taskinstance.py", line 2357, in _run_raw_task
    self._execute_task_with_callbacks(context, test_mode, session=session)
  File "/usr/local/lib/python3.10/dist-packages/airflow/models/taskinstance.py", line 2529, in _execute_task_with_callbacks
    result = self._execute_task(context, task_orig)
  File "/usr/local/lib/python3.10/dist-packages/airflow/models/taskinstance.py", line 2546, in _execute_task
    return _execute_task(self, context, task_orig)
  File "/usr/local/lib/python3.10/dist-packages/airflow/models/taskinstance.py", line 444, in _execute_task
    result = _execute_callable(context=context, **execute_callable_kwargs)
  File "/usr/local/lib/python3.10/dist-packages/airflow/models/taskinstance.py", line 414, in _execute_callable
    return execute_callable(context=context, **execute_callable_kwargs)
  File "/usr/local/lib/python3.10/dist-packages/airflow/operators/python.py", line 200, in execute
    return_value = self.execute_callable()
  File "/usr/local/lib/python3.10/dist-packages/airflow/operators/python.py", line 217, in execute_callable
    return self.python_callable(*self.op_args, **self.op_kwargs)
  File "/home/ubuntu/airflow/pythonScript.py", line 33, in extractData
    earthquakes_df = pd.concat([filter_earthquakes(get_earthquakes(date(2022, 1, 1) - timedelta(i))) for i in range(100)])
  File "/home/ubuntu/airflow/pythonScript.py", line 33, in <listcomp>
    earthquakes_df = pd.concat([filter_earthquakes(get_earthquakes(date(2022, 1, 1) - timedelta(i))) for i in range(100)])
TypeError: 'datetime.date' object is not callable

During handling of the above exception, another exception occurred:

Traceback (most recent call last):
  File "/usr/local/lib/python3.10/dist-packages/airflow/models/taskinstance.py", line 1011, in _email_alert
    send_email(task.email, subject, html_content)
  File "/usr/local/lib/python3.10/dist-packages/airflow/utils/email.py", line 80, in send_email
    return backend(
  File "/usr/local/lib/python3.10/dist-packages/airflow/utils/email.py", line 154, in send_email_smtp
    send_mime_email(e_from=mail_from, e_to=recipients, mime_msg=msg, conn_id=conn_id, dryrun=dryrun)
  File "/usr/local/lib/python3.10/dist-packages/airflow/utils/email.py", line 280, in send_mime_email
    smtp_conn.login(smtp_user, smtp_password)
  File "/usr/lib/python3.10/smtplib.py", line 750, in login
    raise last_exception
  File "/usr/lib/python3.10/smtplib.py", line 739, in login
    (code, resp) = self.auth(
  File "/usr/lib/python3.10/smtplib.py", line 662, in auth
    raise SMTPAuthenticationError(code, resp)
smtplib.SMTPAuthenticationError: (535, b'5.7.8 Username and Password not accepted. For more information, go to\n5.7.8  https://support.google.com/mail/?p=BadCredentials r10-20020a635d0a000000b005dc36279d6dsm5913200pgb.73 - gsmtp')

During handling of the above exception, another exception occurred:

Traceback (most recent call last):
  File "/usr/local/lib/python3.10/dist-packages/airflow/models/taskinstance.py", line 835, in _handle_failure
    task_instance.email_alert(error, failure_context["task"])
  File "/usr/local/lib/python3.10/dist-packages/airflow/models/taskinstance.py", line 2976, in email_alert
    _email_alert(task_instance=self, exception=exception, task=task)
  File "/usr/local/lib/python3.10/dist-packages/airflow/models/taskinstance.py", line 1013, in _email_alert
    send_email(task.email, subject, html_content_err)
  File "/usr/local/lib/python3.10/dist-packages/airflow/utils/email.py", line 80, in send_email
    return backend(
  File "/usr/local/lib/python3.10/dist-packages/airflow/utils/email.py", line 154, in send_email_smtp
    send_mime_email(e_from=mail_from, e_to=recipients, mime_msg=msg, conn_id=conn_id, dryrun=dryrun)
  File "/usr/local/lib/python3.10/dist-packages/airflow/utils/email.py", line 280, in send_mime_email
    smtp_conn.login(smtp_user, smtp_password)
  File "/usr/lib/python3.10/smtplib.py", line 750, in login
    raise last_exception
  File "/usr/lib/python3.10/smtplib.py", line 739, in login
    (code, resp) = self.auth(
  File "/usr/lib/python3.10/smtplib.py", line 662, in auth
    raise SMTPAuthenticationError(code, resp)
smtplib.SMTPAuthenticationError: (535, b'5.7.8 Username and Password not accepted. For more information, go to\n5.7.8  https://support.google.com/mail/?p=BadCredentials i23-20020a631317000000b005ce472f2d0fsm6006768pgl.66 - gsmtp')
[2024-02-27T17:14:10.999+0000] {standard_task_runner.py:107} ERROR - Failed to execute job 43 for task task_extract_earthquake_data ('datetime.date' object is not callable; 12849)
[2024-02-27T17:14:11.034+0000] {local_task_job_runner.py:234} INFO - Task exited with return code 1
[2024-02-27T17:14:11.047+0000] {taskinstance.py:3309} INFO - 0 downstream tasks scheduled from follow-on schedule check
